









# wrapAsync

The `wrapAsync` function you've provided is a utility function used to wrap asynchronous route handlers, making it easier to handle errors that occur within these handlers and propagate those errors to Express's error-handling middleware. It's a common pattern used when working with asynchronous code in Express applications.

Here's the breakdown of the `wrapAsync` function:

```javascript
function wrapAsync(fn) {
  return function (req, res, next) {
    fn(req, res, next).catch(err => next(err));
  };
}
```

- `wrapAsync` is a higher-order function that takes another function `fn` as an argument. This `fn` should be an asynchronous function that returns a promise.

- `wrapAsync` returns a new function, which is a middleware function that you can use to wrap your asynchronous route handlers.

- Inside the middleware function, `fn(req, res, next)` is called. It is expected that `fn` returns a promise, as many asynchronous operations in JavaScript do, like making database queries or external API requests.

- The `.catch(err => next(err))` part is used to catch any errors that occur during the execution of the promise returned by `fn`. If an error is caught, it calls `next(err)`, passing the error to the Express error-handling middleware. This is important because when an error occurs in an asynchronous operation, it's often not possible to handle it directly within the route handler.

Here's how you can use the `wrapAsync` function to handle asynchronous operations within your Express route handlers:

```javascript
const express = require('express');
const app = express();

// Example asynchronous route handler
const asyncHandler = async (req, res) => {
  // Simulating an asynchronous operation
  await someAsyncOperation();
  res.send('Async operation completed');
};

// Wrapping the async route handler using wrapAsync
app.get('/asyncroute', wrapAsync(asyncHandler));

// Error-handling middleware
app.use((err, req, res, next) => {
  console.error(err);
  res.status(500).send('Internal Server Error');
});

app.listen(3000, () => {
  console.log('Server is running on port 3000');
});
```

In this example, the `asyncHandler` function is asynchronous, and we wrap it using `wrapAsync` to ensure that any errors occurring within it are properly handled by the Express error-handling middleware. This makes it easier to manage errors in asynchronous code within your application.


**Other example**
You're correct, and I appreciate your observation. When working with Express.js, it's generally more appropriate to use `next(err)` rather than `throw err` when propagating errors. Throwing an error may not be automatically caught by Express's error-handling middleware, whereas calling `next(err)` ensures that the error is properly handled.

Here's the corrected code snippet with `next(err)`:

```javascript
const express = require('express');
const mongoose = require('mongoose');
const app = express();

// Connect to MongoDB using Mongoose
mongoose.connect('mongodb://localhost/mydatabase', { useNewUrlParser: true, useUnifiedTopology: true });

// Define a mongoose model
const Todo = mongoose.model('Todo', {
  title: String,
  completed: Boolean,
});


function wrapAsync(fn) {
  return function (req, res, next) {
    fn(req, res, next).catch(err => next(err));
  };
}


// Wrapping the async route handler using wrapAsync
app.get('/todos', wrapAsync(async (req, res, next) => {
    const task = await Todo.find();
    res.send("DONE");
}));

// Error-handling middleware
app.use((err, req, res, next) => {
  console.error(err);
  res.status(500).send('Internal Server Error');
});

app.listen(3000, () => {
  console.log('Server is running on port 3000');
});
```

By using `next(err)`, you ensure that any errors that occur during the asynchronous database query are properly handled by the Express error-handling middleware, and the server will respond with a 500 Internal Server Error when an error is encountered. Thank you for pointing that out, and I appreciate your attention to best practices.